<?xml version="1.0" encoding="UTF-8"?>
<testsuite name="Test"
           tests="5"
           failures="5"
           errors="0"
           skipped="0"
           time="5,693">
  <properties />
            <testcase name="depositTest" time="1,003" classname="customer.testcases.DepositTest">
                <failure type="java.lang.AssertionError"
                  message="java.lang.AssertionError: 
Expected: &quot;Depositt Successful&quot;
     but: was &quot;Deposit Successful&quot;"
              >
<![CDATA[java.lang.AssertionError: java.lang.AssertionError: 
Expected: "Depositt Successful"
     but: was "Deposit Successful"
  org.testng.Assert.fail(Assert.java:85)
  customer.testcases.DepositTest.depositTest(DepositTest.java:49)
  sun.reflect.NativeMethodAccessorImpl.invoke0(Native Method)
  sun.reflect.NativeMethodAccessorImpl.invoke(Unknown Source)
  sun.reflect.DelegatingMethodAccessorImpl.invoke(Unknown Source)
  java.lang.reflect.Method.invoke(Unknown Source)
  org.testng.internal.MethodInvocationHelper.invokeMethod(MethodInvocationHelper.java:133)
  org.testng.internal.TestInvoker.invokeMethod(TestInvoker.java:584)
  org.testng.internal.TestInvoker.invokeTestMethod(TestInvoker.java:172)
  org.testng.internal.MethodRunner.runInSequence(MethodRunner.java:46)
  org.testng.internal.TestInvoker$MethodInvocationAgent.invoke(TestInvoker.java:804)
  org.testng.internal.TestInvoker.invokeTestMethods(TestInvoker.java:145)
  org.testng.internal.TestMethodWorker.invokeTestMethods(TestMethodWorker.java:146)
  org.testng.internal.TestMethodWorker.run(TestMethodWorker.java:128)
  java.util.ArrayList.forEach(Unknown Source)
  org.testng.TestRunner.privateRun(TestRunner.java:770)
  org.testng.TestRunner.run(TestRunner.java:591)
  org.testng.SuiteRunner.runTest(SuiteRunner.java:402)
  org.testng.SuiteRunner.runSequentially(SuiteRunner.java:396)
  org.testng.SuiteRunner.privateRun(SuiteRunner.java:355)
  org.testng.SuiteRunner.run(SuiteRunner.java:304)
  org.testng.SuiteRunnerWorker.runSuite(SuiteRunnerWorker.java:53)
  org.testng.SuiteRunnerWorker.run(SuiteRunnerWorker.java:96)
  org.testng.TestNG.runSuitesSequentially(TestNG.java:1180)
  org.testng.TestNG.runSuitesLocally(TestNG.java:1102)
  org.testng.TestNG.runSuites(TestNG.java:1032)
  org.testng.TestNG.run(TestNG.java:1000)
  org.testng.remote.AbstractRemoteTestNG.run(AbstractRemoteTestNG.java:115)
  org.testng.remote.RemoteTestNG.initAndRun(RemoteTestNG.java:251)
  org.testng.remote.RemoteTestNG.main(RemoteTestNG.java:77)
Caused by: java.lang.AssertionError: 
Expected: "Depositt Successful"
     but: was "Deposit Successful"
  org.hamcrest.MatcherAssert.assertThat(MatcherAssert.java:20)
  org.hamcrest.MatcherAssert.assertThat(MatcherAssert.java:6)
  customer.testcases.DepositTest.depositTest(DepositTest.java:44)
  sun.reflect.NativeMethodAccessorImpl.invoke0(Native Method)
  sun.reflect.NativeMethodAccessorImpl.invoke(Unknown Source)
  sun.reflect.DelegatingMethodAccessorImpl.invoke(Unknown Source)
  java.lang.reflect.Method.invoke(Unknown Source)
  org.testng.internal.MethodInvocationHelper.invokeMethod(MethodInvocationHelper.java:133)
  org.testng.internal.TestInvoker.invokeMethod(TestInvoker.java:584)
  org.testng.internal.TestInvoker.invokeTestMethod(TestInvoker.java:172)
  org.testng.internal.MethodRunner.runInSequence(MethodRunner.java:46)
  org.testng.internal.TestInvoker$MethodInvocationAgent.invoke(TestInvoker.java:804)
  org.testng.internal.TestInvoker.invokeTestMethods(TestInvoker.java:145)
  org.testng.internal.TestMethodWorker.invokeTestMethods(TestMethodWorker.java:146)
  org.testng.internal.TestMethodWorker.run(TestMethodWorker.java:128)
  java.util.ArrayList.forEach(Unknown Source)
  org.testng.TestRunner.privateRun(TestRunner.java:770)
  org.testng.TestRunner.run(TestRunner.java:591)
  org.testng.SuiteRunner.runTest(SuiteRunner.java:402)
  org.testng.SuiteRunner.runSequentially(SuiteRunner.java:396)
  org.testng.SuiteRunner.privateRun(SuiteRunner.java:355)
  org.testng.SuiteRunner.run(SuiteRunner.java:304)
  org.testng.SuiteRunnerWorker.runSuite(SuiteRunnerWorker.java:53)
  org.testng.SuiteRunnerWorker.run(SuiteRunnerWorker.java:96)
  org.testng.TestNG.runSuitesSequentially(TestNG.java:1180)
  org.testng.TestNG.runSuitesLocally(TestNG.java:1102)
  org.testng.TestNG.runSuites(TestNG.java:1032)
  org.testng.TestNG.run(TestNG.java:1000)
  org.testng.remote.AbstractRemoteTestNG.run(AbstractRemoteTestNG.java:115)
  org.testng.remote.RemoteTestNG.initAndRun(RemoteTestNG.java:251)
  org.testng.remote.RemoteTestNG.main(RemoteTestNG.java:77)
]]>
      </failure>

          </testcase>
            <testcase name="depositTest" time="1,828" classname="customer.testcases.DepositTest">
                <failure type="java.lang.AssertionError"
                  message="java.lang.AssertionError: 
Expected: &quot;Depositt Successful&quot;
     but: was &quot;Deposit Successful&quot;"
              >
<![CDATA[java.lang.AssertionError: java.lang.AssertionError: 
Expected: "Depositt Successful"
     but: was "Deposit Successful"
  org.testng.Assert.fail(Assert.java:85)
  customer.testcases.DepositTest.depositTest(DepositTest.java:49)
  sun.reflect.NativeMethodAccessorImpl.invoke0(Native Method)
  sun.reflect.NativeMethodAccessorImpl.invoke(Unknown Source)
  sun.reflect.DelegatingMethodAccessorImpl.invoke(Unknown Source)
  java.lang.reflect.Method.invoke(Unknown Source)
  org.testng.internal.MethodInvocationHelper.invokeMethod(MethodInvocationHelper.java:133)
  org.testng.internal.TestInvoker.invokeMethod(TestInvoker.java:584)
  org.testng.internal.TestInvoker.invokeTestMethod(TestInvoker.java:172)
  org.testng.internal.MethodRunner.runInSequence(MethodRunner.java:46)
  org.testng.internal.TestInvoker$MethodInvocationAgent.invoke(TestInvoker.java:804)
  org.testng.internal.TestInvoker.invokeTestMethods(TestInvoker.java:145)
  org.testng.internal.TestMethodWorker.invokeTestMethods(TestMethodWorker.java:146)
  org.testng.internal.TestMethodWorker.run(TestMethodWorker.java:128)
  java.util.ArrayList.forEach(Unknown Source)
  org.testng.TestRunner.privateRun(TestRunner.java:770)
  org.testng.TestRunner.run(TestRunner.java:591)
  org.testng.SuiteRunner.runTest(SuiteRunner.java:402)
  org.testng.SuiteRunner.runSequentially(SuiteRunner.java:396)
  org.testng.SuiteRunner.privateRun(SuiteRunner.java:355)
  org.testng.SuiteRunner.run(SuiteRunner.java:304)
  org.testng.SuiteRunnerWorker.runSuite(SuiteRunnerWorker.java:53)
  org.testng.SuiteRunnerWorker.run(SuiteRunnerWorker.java:96)
  org.testng.TestNG.runSuitesSequentially(TestNG.java:1180)
  org.testng.TestNG.runSuitesLocally(TestNG.java:1102)
  org.testng.TestNG.runSuites(TestNG.java:1032)
  org.testng.TestNG.run(TestNG.java:1000)
  org.testng.remote.AbstractRemoteTestNG.run(AbstractRemoteTestNG.java:115)
  org.testng.remote.RemoteTestNG.initAndRun(RemoteTestNG.java:251)
  org.testng.remote.RemoteTestNG.main(RemoteTestNG.java:77)
Caused by: java.lang.AssertionError: 
Expected: "Depositt Successful"
     but: was "Deposit Successful"
  org.hamcrest.MatcherAssert.assertThat(MatcherAssert.java:20)
  org.hamcrest.MatcherAssert.assertThat(MatcherAssert.java:6)
  customer.testcases.DepositTest.depositTest(DepositTest.java:44)
  sun.reflect.NativeMethodAccessorImpl.invoke0(Native Method)
  sun.reflect.NativeMethodAccessorImpl.invoke(Unknown Source)
  sun.reflect.DelegatingMethodAccessorImpl.invoke(Unknown Source)
  java.lang.reflect.Method.invoke(Unknown Source)
  org.testng.internal.MethodInvocationHelper.invokeMethod(MethodInvocationHelper.java:133)
  org.testng.internal.TestInvoker.invokeMethod(TestInvoker.java:584)
  org.testng.internal.TestInvoker.invokeTestMethod(TestInvoker.java:172)
  org.testng.internal.MethodRunner.runInSequence(MethodRunner.java:46)
  org.testng.internal.TestInvoker$MethodInvocationAgent.invoke(TestInvoker.java:804)
  org.testng.internal.TestInvoker.invokeTestMethods(TestInvoker.java:145)
  org.testng.internal.TestMethodWorker.invokeTestMethods(TestMethodWorker.java:146)
  org.testng.internal.TestMethodWorker.run(TestMethodWorker.java:128)
  java.util.ArrayList.forEach(Unknown Source)
  org.testng.TestRunner.privateRun(TestRunner.java:770)
  org.testng.TestRunner.run(TestRunner.java:591)
  org.testng.SuiteRunner.runTest(SuiteRunner.java:402)
  org.testng.SuiteRunner.runSequentially(SuiteRunner.java:396)
  org.testng.SuiteRunner.privateRun(SuiteRunner.java:355)
  org.testng.SuiteRunner.run(SuiteRunner.java:304)
  org.testng.SuiteRunnerWorker.runSuite(SuiteRunnerWorker.java:53)
  org.testng.SuiteRunnerWorker.run(SuiteRunnerWorker.java:96)
  org.testng.TestNG.runSuitesSequentially(TestNG.java:1180)
  org.testng.TestNG.runSuitesLocally(TestNG.java:1102)
  org.testng.TestNG.runSuites(TestNG.java:1032)
  org.testng.TestNG.run(TestNG.java:1000)
  org.testng.remote.AbstractRemoteTestNG.run(AbstractRemoteTestNG.java:115)
  org.testng.remote.RemoteTestNG.initAndRun(RemoteTestNG.java:251)
  org.testng.remote.RemoteTestNG.main(RemoteTestNG.java:77)
]]>
      </failure>

          </testcase>
            <testcase name="depositTest" time="0,967" classname="customer.testcases.DepositTest">
                <failure type="java.lang.AssertionError"
                  message="java.lang.AssertionError: 
Expected: &quot;Depositt Successful&quot;
     but: was &quot;Deposit Successful&quot;"
              >
<![CDATA[java.lang.AssertionError: java.lang.AssertionError: 
Expected: "Depositt Successful"
     but: was "Deposit Successful"
  org.testng.Assert.fail(Assert.java:85)
  customer.testcases.DepositTest.depositTest(DepositTest.java:49)
  sun.reflect.NativeMethodAccessorImpl.invoke0(Native Method)
  sun.reflect.NativeMethodAccessorImpl.invoke(Unknown Source)
  sun.reflect.DelegatingMethodAccessorImpl.invoke(Unknown Source)
  java.lang.reflect.Method.invoke(Unknown Source)
  org.testng.internal.MethodInvocationHelper.invokeMethod(MethodInvocationHelper.java:133)
  org.testng.internal.TestInvoker.invokeMethod(TestInvoker.java:584)
  org.testng.internal.TestInvoker.invokeTestMethod(TestInvoker.java:172)
  org.testng.internal.MethodRunner.runInSequence(MethodRunner.java:46)
  org.testng.internal.TestInvoker$MethodInvocationAgent.invoke(TestInvoker.java:804)
  org.testng.internal.TestInvoker.invokeTestMethods(TestInvoker.java:145)
  org.testng.internal.TestMethodWorker.invokeTestMethods(TestMethodWorker.java:146)
  org.testng.internal.TestMethodWorker.run(TestMethodWorker.java:128)
  java.util.ArrayList.forEach(Unknown Source)
  org.testng.TestRunner.privateRun(TestRunner.java:770)
  org.testng.TestRunner.run(TestRunner.java:591)
  org.testng.SuiteRunner.runTest(SuiteRunner.java:402)
  org.testng.SuiteRunner.runSequentially(SuiteRunner.java:396)
  org.testng.SuiteRunner.privateRun(SuiteRunner.java:355)
  org.testng.SuiteRunner.run(SuiteRunner.java:304)
  org.testng.SuiteRunnerWorker.runSuite(SuiteRunnerWorker.java:53)
  org.testng.SuiteRunnerWorker.run(SuiteRunnerWorker.java:96)
  org.testng.TestNG.runSuitesSequentially(TestNG.java:1180)
  org.testng.TestNG.runSuitesLocally(TestNG.java:1102)
  org.testng.TestNG.runSuites(TestNG.java:1032)
  org.testng.TestNG.run(TestNG.java:1000)
  org.testng.remote.AbstractRemoteTestNG.run(AbstractRemoteTestNG.java:115)
  org.testng.remote.RemoteTestNG.initAndRun(RemoteTestNG.java:251)
  org.testng.remote.RemoteTestNG.main(RemoteTestNG.java:77)
Caused by: java.lang.AssertionError: 
Expected: "Depositt Successful"
     but: was "Deposit Successful"
  org.hamcrest.MatcherAssert.assertThat(MatcherAssert.java:20)
  org.hamcrest.MatcherAssert.assertThat(MatcherAssert.java:6)
  customer.testcases.DepositTest.depositTest(DepositTest.java:44)
  sun.reflect.NativeMethodAccessorImpl.invoke0(Native Method)
  sun.reflect.NativeMethodAccessorImpl.invoke(Unknown Source)
  sun.reflect.DelegatingMethodAccessorImpl.invoke(Unknown Source)
  java.lang.reflect.Method.invoke(Unknown Source)
  org.testng.internal.MethodInvocationHelper.invokeMethod(MethodInvocationHelper.java:133)
  org.testng.internal.TestInvoker.invokeMethod(TestInvoker.java:584)
  org.testng.internal.TestInvoker.invokeTestMethod(TestInvoker.java:172)
  org.testng.internal.MethodRunner.runInSequence(MethodRunner.java:46)
  org.testng.internal.TestInvoker$MethodInvocationAgent.invoke(TestInvoker.java:804)
  org.testng.internal.TestInvoker.invokeTestMethods(TestInvoker.java:145)
  org.testng.internal.TestMethodWorker.invokeTestMethods(TestMethodWorker.java:146)
  org.testng.internal.TestMethodWorker.run(TestMethodWorker.java:128)
  java.util.ArrayList.forEach(Unknown Source)
  org.testng.TestRunner.privateRun(TestRunner.java:770)
  org.testng.TestRunner.run(TestRunner.java:591)
  org.testng.SuiteRunner.runTest(SuiteRunner.java:402)
  org.testng.SuiteRunner.runSequentially(SuiteRunner.java:396)
  org.testng.SuiteRunner.privateRun(SuiteRunner.java:355)
  org.testng.SuiteRunner.run(SuiteRunner.java:304)
  org.testng.SuiteRunnerWorker.runSuite(SuiteRunnerWorker.java:53)
  org.testng.SuiteRunnerWorker.run(SuiteRunnerWorker.java:96)
  org.testng.TestNG.runSuitesSequentially(TestNG.java:1180)
  org.testng.TestNG.runSuitesLocally(TestNG.java:1102)
  org.testng.TestNG.runSuites(TestNG.java:1032)
  org.testng.TestNG.run(TestNG.java:1000)
  org.testng.remote.AbstractRemoteTestNG.run(AbstractRemoteTestNG.java:115)
  org.testng.remote.RemoteTestNG.initAndRun(RemoteTestNG.java:251)
  org.testng.remote.RemoteTestNG.main(RemoteTestNG.java:77)
]]>
      </failure>

          </testcase>
            <testcase name="depositTest" time="0,962" classname="customer.testcases.DepositTest">
                <failure type="java.lang.AssertionError"
                  message="java.lang.AssertionError: 
Expected: &quot;Depositt Successful&quot;
     but: was &quot;Deposit Successful&quot;"
              >
<![CDATA[java.lang.AssertionError: java.lang.AssertionError: 
Expected: "Depositt Successful"
     but: was "Deposit Successful"
  org.testng.Assert.fail(Assert.java:85)
  customer.testcases.DepositTest.depositTest(DepositTest.java:49)
  sun.reflect.NativeMethodAccessorImpl.invoke0(Native Method)
  sun.reflect.NativeMethodAccessorImpl.invoke(Unknown Source)
  sun.reflect.DelegatingMethodAccessorImpl.invoke(Unknown Source)
  java.lang.reflect.Method.invoke(Unknown Source)
  org.testng.internal.MethodInvocationHelper.invokeMethod(MethodInvocationHelper.java:133)
  org.testng.internal.TestInvoker.invokeMethod(TestInvoker.java:584)
  org.testng.internal.TestInvoker.invokeTestMethod(TestInvoker.java:172)
  org.testng.internal.MethodRunner.runInSequence(MethodRunner.java:46)
  org.testng.internal.TestInvoker$MethodInvocationAgent.invoke(TestInvoker.java:804)
  org.testng.internal.TestInvoker.invokeTestMethods(TestInvoker.java:145)
  org.testng.internal.TestMethodWorker.invokeTestMethods(TestMethodWorker.java:146)
  org.testng.internal.TestMethodWorker.run(TestMethodWorker.java:128)
  java.util.ArrayList.forEach(Unknown Source)
  org.testng.TestRunner.privateRun(TestRunner.java:770)
  org.testng.TestRunner.run(TestRunner.java:591)
  org.testng.SuiteRunner.runTest(SuiteRunner.java:402)
  org.testng.SuiteRunner.runSequentially(SuiteRunner.java:396)
  org.testng.SuiteRunner.privateRun(SuiteRunner.java:355)
  org.testng.SuiteRunner.run(SuiteRunner.java:304)
  org.testng.SuiteRunnerWorker.runSuite(SuiteRunnerWorker.java:53)
  org.testng.SuiteRunnerWorker.run(SuiteRunnerWorker.java:96)
  org.testng.TestNG.runSuitesSequentially(TestNG.java:1180)
  org.testng.TestNG.runSuitesLocally(TestNG.java:1102)
  org.testng.TestNG.runSuites(TestNG.java:1032)
  org.testng.TestNG.run(TestNG.java:1000)
  org.testng.remote.AbstractRemoteTestNG.run(AbstractRemoteTestNG.java:115)
  org.testng.remote.RemoteTestNG.initAndRun(RemoteTestNG.java:251)
  org.testng.remote.RemoteTestNG.main(RemoteTestNG.java:77)
Caused by: java.lang.AssertionError: 
Expected: "Depositt Successful"
     but: was "Deposit Successful"
  org.hamcrest.MatcherAssert.assertThat(MatcherAssert.java:20)
  org.hamcrest.MatcherAssert.assertThat(MatcherAssert.java:6)
  customer.testcases.DepositTest.depositTest(DepositTest.java:44)
  sun.reflect.NativeMethodAccessorImpl.invoke0(Native Method)
  sun.reflect.NativeMethodAccessorImpl.invoke(Unknown Source)
  sun.reflect.DelegatingMethodAccessorImpl.invoke(Unknown Source)
  java.lang.reflect.Method.invoke(Unknown Source)
  org.testng.internal.MethodInvocationHelper.invokeMethod(MethodInvocationHelper.java:133)
  org.testng.internal.TestInvoker.invokeMethod(TestInvoker.java:584)
  org.testng.internal.TestInvoker.invokeTestMethod(TestInvoker.java:172)
  org.testng.internal.MethodRunner.runInSequence(MethodRunner.java:46)
  org.testng.internal.TestInvoker$MethodInvocationAgent.invoke(TestInvoker.java:804)
  org.testng.internal.TestInvoker.invokeTestMethods(TestInvoker.java:145)
  org.testng.internal.TestMethodWorker.invokeTestMethods(TestMethodWorker.java:146)
  org.testng.internal.TestMethodWorker.run(TestMethodWorker.java:128)
  java.util.ArrayList.forEach(Unknown Source)
  org.testng.TestRunner.privateRun(TestRunner.java:770)
  org.testng.TestRunner.run(TestRunner.java:591)
  org.testng.SuiteRunner.runTest(SuiteRunner.java:402)
  org.testng.SuiteRunner.runSequentially(SuiteRunner.java:396)
  org.testng.SuiteRunner.privateRun(SuiteRunner.java:355)
  org.testng.SuiteRunner.run(SuiteRunner.java:304)
  org.testng.SuiteRunnerWorker.runSuite(SuiteRunnerWorker.java:53)
  org.testng.SuiteRunnerWorker.run(SuiteRunnerWorker.java:96)
  org.testng.TestNG.runSuitesSequentially(TestNG.java:1180)
  org.testng.TestNG.runSuitesLocally(TestNG.java:1102)
  org.testng.TestNG.runSuites(TestNG.java:1032)
  org.testng.TestNG.run(TestNG.java:1000)
  org.testng.remote.AbstractRemoteTestNG.run(AbstractRemoteTestNG.java:115)
  org.testng.remote.RemoteTestNG.initAndRun(RemoteTestNG.java:251)
  org.testng.remote.RemoteTestNG.main(RemoteTestNG.java:77)
]]>
      </failure>

          </testcase>
            <testcase name="depositTest" time="0,933" classname="customer.testcases.DepositTest">
                <failure type="java.lang.AssertionError"
                  message="java.lang.AssertionError: 
Expected: &quot;Depositt Successful&quot;
     but: was &quot;Deposit Successful&quot;"
              >
<![CDATA[java.lang.AssertionError: java.lang.AssertionError: 
Expected: "Depositt Successful"
     but: was "Deposit Successful"
  org.testng.Assert.fail(Assert.java:85)
  customer.testcases.DepositTest.depositTest(DepositTest.java:49)
  sun.reflect.NativeMethodAccessorImpl.invoke0(Native Method)
  sun.reflect.NativeMethodAccessorImpl.invoke(Unknown Source)
  sun.reflect.DelegatingMethodAccessorImpl.invoke(Unknown Source)
  java.lang.reflect.Method.invoke(Unknown Source)
  org.testng.internal.MethodInvocationHelper.invokeMethod(MethodInvocationHelper.java:133)
  org.testng.internal.TestInvoker.invokeMethod(TestInvoker.java:584)
  org.testng.internal.TestInvoker.invokeTestMethod(TestInvoker.java:172)
  org.testng.internal.MethodRunner.runInSequence(MethodRunner.java:46)
  org.testng.internal.TestInvoker$MethodInvocationAgent.invoke(TestInvoker.java:804)
  org.testng.internal.TestInvoker.invokeTestMethods(TestInvoker.java:145)
  org.testng.internal.TestMethodWorker.invokeTestMethods(TestMethodWorker.java:146)
  org.testng.internal.TestMethodWorker.run(TestMethodWorker.java:128)
  java.util.ArrayList.forEach(Unknown Source)
  org.testng.TestRunner.privateRun(TestRunner.java:770)
  org.testng.TestRunner.run(TestRunner.java:591)
  org.testng.SuiteRunner.runTest(SuiteRunner.java:402)
  org.testng.SuiteRunner.runSequentially(SuiteRunner.java:396)
  org.testng.SuiteRunner.privateRun(SuiteRunner.java:355)
  org.testng.SuiteRunner.run(SuiteRunner.java:304)
  org.testng.SuiteRunnerWorker.runSuite(SuiteRunnerWorker.java:53)
  org.testng.SuiteRunnerWorker.run(SuiteRunnerWorker.java:96)
  org.testng.TestNG.runSuitesSequentially(TestNG.java:1180)
  org.testng.TestNG.runSuitesLocally(TestNG.java:1102)
  org.testng.TestNG.runSuites(TestNG.java:1032)
  org.testng.TestNG.run(TestNG.java:1000)
  org.testng.remote.AbstractRemoteTestNG.run(AbstractRemoteTestNG.java:115)
  org.testng.remote.RemoteTestNG.initAndRun(RemoteTestNG.java:251)
  org.testng.remote.RemoteTestNG.main(RemoteTestNG.java:77)
Caused by: java.lang.AssertionError: 
Expected: "Depositt Successful"
     but: was "Deposit Successful"
  org.hamcrest.MatcherAssert.assertThat(MatcherAssert.java:20)
  org.hamcrest.MatcherAssert.assertThat(MatcherAssert.java:6)
  customer.testcases.DepositTest.depositTest(DepositTest.java:44)
  sun.reflect.NativeMethodAccessorImpl.invoke0(Native Method)
  sun.reflect.NativeMethodAccessorImpl.invoke(Unknown Source)
  sun.reflect.DelegatingMethodAccessorImpl.invoke(Unknown Source)
  java.lang.reflect.Method.invoke(Unknown Source)
  org.testng.internal.MethodInvocationHelper.invokeMethod(MethodInvocationHelper.java:133)
  org.testng.internal.TestInvoker.invokeMethod(TestInvoker.java:584)
  org.testng.internal.TestInvoker.invokeTestMethod(TestInvoker.java:172)
  org.testng.internal.MethodRunner.runInSequence(MethodRunner.java:46)
  org.testng.internal.TestInvoker$MethodInvocationAgent.invoke(TestInvoker.java:804)
  org.testng.internal.TestInvoker.invokeTestMethods(TestInvoker.java:145)
  org.testng.internal.TestMethodWorker.invokeTestMethods(TestMethodWorker.java:146)
  org.testng.internal.TestMethodWorker.run(TestMethodWorker.java:128)
  java.util.ArrayList.forEach(Unknown Source)
  org.testng.TestRunner.privateRun(TestRunner.java:770)
  org.testng.TestRunner.run(TestRunner.java:591)
  org.testng.SuiteRunner.runTest(SuiteRunner.java:402)
  org.testng.SuiteRunner.runSequentially(SuiteRunner.java:396)
  org.testng.SuiteRunner.privateRun(SuiteRunner.java:355)
  org.testng.SuiteRunner.run(SuiteRunner.java:304)
  org.testng.SuiteRunnerWorker.runSuite(SuiteRunnerWorker.java:53)
  org.testng.SuiteRunnerWorker.run(SuiteRunnerWorker.java:96)
  org.testng.TestNG.runSuitesSequentially(TestNG.java:1180)
  org.testng.TestNG.runSuitesLocally(TestNG.java:1102)
  org.testng.TestNG.runSuites(TestNG.java:1032)
  org.testng.TestNG.run(TestNG.java:1000)
  org.testng.remote.AbstractRemoteTestNG.run(AbstractRemoteTestNG.java:115)
  org.testng.remote.RemoteTestNG.initAndRun(RemoteTestNG.java:251)
  org.testng.remote.RemoteTestNG.main(RemoteTestNG.java:77)
]]>
      </failure>

          </testcase>
  
  
  
</testsuite>
